## panic与recover
F函数调用panic后程序将不会执行F后面的代码，如果是协程中调用panic，那么将会只终止协程的运行，主线程不受影响；如果F函数调用panic，在panic调用之前定义了defer，在panic执行后，程序不会马上退出，而会先执行defer内的语句再退出；如果F函数在defer内执行了recover函数，则它能阻止panic对程序的终止，获取panic的内容，此时不会F函数panic之后后的语句，F函数的调用函数G，将继续执行后面的代码
```go
package main

func main() {
    test()
}

func test() {
    defer func() {
        if err := recover(); err != nil {
            println(err.(string)) // 将 interface{} 转型为具体类型。
        }
    }()

    panic("panic error!")
}
```

## errors.New
创建一个标准库error类型

```go
package main  
  
import (  
    "errors"  
    "fmt")  
  
var Err = errors.New("division by zero")  
  
func division(x int, y int) (int, error) {  
    if y == 0 {  
       return 0, Err  
    }  
    return x / y, nil  
}  
  
func main() {  
    _, err := division(7, 0)  
    if err != nil {  
       fmt.Println(err)  
    }  
}
//division by zero
```

自定义error
```go
package main  
  
import (  
    "fmt"  
)  
  
var Err = MyError{404}  
  
type MyError struct {  
    i int  
}  
  
func (e MyError) Error() string {  
    return fmt.Sprintf("MyError %d", e.i)  
}  
  
func division(x int, y int) (int, error) {  
    if y == 0 {  
       return 0, Err  
    }  
    return x / y, nil  
}  
  
func main() {  
    _, err := division(7, 0)  
    if err != nil {  
       fmt.Println(err)  
    }  
}
```

## fmt.Errorf
```go
package main  
  
import (  
    "errors"  
    "fmt")  
  
func division(x int, y int) (int, error) {  
    if y == 0 {  
       return 0, fmt.Errorf("MyError2 %d", 403)  
    }  
    return x / y, nil  
}  
  
func main() {  
    _, err := division(7, 0)  
    if err != nil {  
       fmt.Println(err)  
    }  
}
```